#VRML_SIM R2023a utf8

EXTERNPROTO "https://raw.githubusercontent.com/cyberbotics/webots/R2023a/projects/objects/backgrounds/protos/TexturedBackgroundLight.proto"
EXTERNPROTO "https://raw.githubusercontent.com/cyberbotics/webots/R2023a/projects/objects/floors/protos/RectangleArena.proto"
EXTERNPROTO "https://raw.githubusercontent.com/cyberbotics/webots/R2023a/projects/objects/apartment_structure/protos/Wall.proto"
EXTERNPROTO "https://raw.githubusercontent.com/cyberbotics/webots/R2023a/projects/appearances/protos/Parquetry.proto"

WorldInfo {
}
Viewpoint {
  orientation -0.5765007046853114 0.572856040214705 0.5826516066114188 2.069964121245501
  position -0.13875840931038408 -0.25136825675562563 10.77685639700114
  follow "rectangle arena"
}
TexturedBackgroundLight {
}
RectangleArena {
  floorSize 5 5
  floorAppearance Parquetry {
    type "chequered"
    colorOverride 0.392157 0.545098 0.784314
    IBLStrength 6
  }
  wallThickness 0.1
}
Robot {
  translation -2.3486699337666677 -2.1174199544558796 -0.002105136981542372
  rotation 0 0 1 3.14
  children [
    Receiver {
      type "serial"
    }
    Emitter {
      type "serial"
      channel 1
    }
    DEF Body Transform {
      translation 0 0 0.0255
      children [
        Shape {
          appearance PBRAppearance {
            roughness 1
            metalness 0
          }
          geometry Cylinder {
            height 0.019
            radius 0.075
          }
        }
      ]
    }
    Transform {
      translation 0 0 0.016
      scale 0.001 0.001 0.001
      children [
        Shape {
          appearance PBRAppearance {
            roughness 1
            metalness 0
          }
          geometry Mesh {
            url [
              "../Modelos_3D/Pololu/BumperV2.stl"
            ]
          }
        }
      ]
    }
    Transform {
      translation 0 0 0.0165
      rotation 0 0 1 3.141
      scale 0.001 0.001 0.001
      children [
        Shape {
          appearance PBRAppearance {
            baseColor 0.454902 0.462745 0.419608
            roughness 1
            metalness 0
          }
          geometry Mesh {
            url [
              "../Modelos_3D/Pololu/BaseSensorDistancia Proto2.stl"
            ]
          }
        }
      ]
    }
    DEF BaseSensores Solid {
      children [
        DistanceSensor {
          translation 0 0 0.085
          rotation 0 0 -1 1.5699996938995748
          name "ds_0"
          lookupTable [
            0 0 0
            2 200 0
          ]
          type "laser"
          aperture 0.01
        }
        Compass {
          translation 0 0 0.085
          rotation 0 0 -1 1.57
        }
        DistanceSensor {
          translation 0 0 0.085
          rotation 0 0 1 -2.353185307179586
          name "ds_1"
          lookupTable [
            0 0 0
            2 200 0
          ]
          type "laser"
          aperture 0.01
        }
        DistanceSensor {
          translation 0 0 0.085
          rotation 0 0 1 3.14
          name "ds_2"
          lookupTable [
            0 0 0
            2 200 0
          ]
          type "laser"
          aperture 0.01
        }
        DistanceSensor {
          translation 0 0 0.085
          rotation 0 0 1 1.57
          name "ds_3"
          lookupTable [
            0 0 0
            2 200 0
          ]
          type "laser"
          aperture 0.01
        }
        GPS {
        }
        DistanceSensor {
          translation 0 0 0.085
          name "ds_4"
          lookupTable [
            0 0 0
            2 200 0
          ]
          type "laser"
          aperture 0.01
          resolution 1
        }
        DistanceSensor {
          translation 0 0 0.085
          rotation 0 0 1 -0.7831853071795862
          name "ds_5"
          lookupTable [
            0 0 0
            2 200 0
          ]
          type "laser"
          aperture 0.01
        }
      ]
      name "solid(4)"
    }
    HingeJoint {
      jointParameters HingeJointParameters {
        position 129.75320362297518
        anchor 0.07 0 0.037
      }
      device [
        PositionSensor {
          name "PositionSensor_1"
        }
        RotationalMotor {
          name "motor_1"
        }
      ]
      endPoint Solid {
        translation 0.06999999999204387 -4.845375467681428e-06 0.03699604087670028
        rotation -0.06065038328749632 0.9963147268762609 -0.060650606069202743 1.5744920720594044
        children [
          DEF wheel_1 Shape {
            appearance PBRAppearance {
              baseColor 0 0 0
              roughness 1
              metalness 0
            }
            geometry Cylinder {
              height 0.01
              radius 0.035
            }
          }
        ]
        contactMaterial "rubber"
        boundingObject USE wheel_1
        physics Physics {
        }
      }
    }
    HingeJoint {
      jointParameters HingeJointParameters {
        position 174.24681540011767
        anchor -0.07 0 0.037
      }
      device [
        PositionSensor {
          name "PositionSensor_2"
        }
        RotationalMotor {
          name "motor_2"
        }
      ]
      endPoint Solid {
        translation -0.07 9.82533108014563e-07 0.03699195981165074
        rotation 0.06065038326922863 0.9963147268784849 0.060650606050934815 1.5744920720571725
        children [
          DEF wheel_2 Shape {
            appearance PBRAppearance {
              baseColor 0 0 0
              roughness 1
              metalness 0
            }
            geometry Cylinder {
              height 0.01
              radius 0.035
            }
          }
        ]
        name "solid(1)"
        contactMaterial "rubber"
        boundingObject USE wheel_2
        physics Physics {
        }
      }
    }
    BallJoint {
      jointParameters BallJointParameters {
        position -8.145252730687245
        anchor 0 0.06 0.012
      }
      jointParameters2 JointParameters {
        position -11.027096720648924
        axis 1 0 0
      }
      jointParameters3 JointParameters {
        position -46.62239980569589
        axis 0 1 0
      }
      endPoint Solid {
        translation -2.3283543740338806e-05 0.060051203005925154 0.012004320146964724
        rotation 0.3094901176850106 -0.9154075651865963 0.2573807620131423 1.8129855820840095
        children [
          DEF CasterBall_1 Shape {
            appearance PBRAppearance {
              baseColor 0.333333 0.333333 0.498039
              roughness 1
              metalness 0
            }
            geometry Sphere {
              radius 0.01
            }
          }
        ]
        name "solid(2)"
        boundingObject USE CasterBall_1
        physics Physics {
        }
      }
    }
    BallJoint {
      jointParameters BallJointParameters {
        position 11.190551780782569
        anchor 0 -0.06 0.012
      }
      jointParameters2 JointParameters {
        position -2.065190201772811
        axis 1 0 0
      }
      jointParameters3 JointParameters {
        position 45.49231684007855
        axis 0 1 0
      }
      endPoint Solid {
        translation 2.0468454969692178e-05 -0.06005270716880564 0.011995349164790533
        rotation 0.7475047993158702 0.5141469632004313 0.42058230494341436 2.5522592545365006
        children [
          DEF CasterBall_2 Shape {
            appearance PBRAppearance {
              baseColor 0.333333 0.333333 0.498039
              roughness 1
              metalness 0
            }
            geometry Sphere {
              radius 0.01
            }
          }
        ]
        name "solid(3)"
        boundingObject USE CasterBall_2
        physics Physics {
        }
      }
    }
  ]
  name "ROBOT_1"
  contactMaterial "plastic"
  boundingObject USE Body
  physics Physics {
  }
  controller "Controlador_VD"
  selfCollision TRUE
}
DEF wall(5) Wall {
  translation 1.59 1.93 0
  rotation 0 0 1 -1.5707953071795862
  name "wall(5)"
  size 1 0.08 0.1
}
DEF wall(0) Wall {
  translation 1.48 1.93 0
  rotation 0 0 1 1.5708
  name "wall(0)"
  size 1 0.08 0.1
}
DEF wall(3) Wall {
  translation 1.37 1.93 0
  rotation 0 0 1 -1.5707953071795862
  name "wall(3)"
  size 1 0.08 0.1
}
DEF wall(8) Wall {
  translation 2.32001 0.840009 0
  rotation 0 0 1 1.5708
  name "wall(8)"
  size 3.2 0.08 0.1
}
DEF wall(2) Wall {
  translation 1.82 1.43 0
  rotation 0 0 1 -1.5707953071795862
  name "wall(2)"
  size 2 0.08 0.1
}
DEF wall(7) Wall {
  translation 1.7 1.93 0
  rotation 0 0 1 1.5708
  name "wall(7)"
  size 1 0.08 0.1
}
DEF wall(9) Wall {
  translation 2.19999 1.43 0
  rotation 0 0 1 1.5708
  name "wall(9)"
  size 2 0.08 0.1
}
DEF wall(6) Wall {
  translation 2.07 1.43001 0
  rotation 0 0 1 1.5708
  name "wall(6)"
  size 2 0.08 0.1
}
DEF wall(1) Wall {
  translation 2.45 0.440027 0
  rotation 0 0 1 1.5708
  name "wall(1)"
  size 4 0.08 0.1
}
DEF wall(4) Wall {
  translation 1.93999 1.43001 0
  rotation 0 0 1 1.5708
  name "wall(4)"
  size 2 0.08 0.1
}
DEF PLACA_1 Solid {
  translation -2.35 -2.11 0.001
  children [
    DEF PLACA_1_Shape Shape {
      appearance PBRAppearance {
        baseColor 0 1 0
        roughness 1
        metalness 0
      }
      geometry Plane {
        size 0.25 0.25
      }
    }
  ]
}
DEF BOX_0 Solid {
  translation 0.737397 2.265 0.15
  rotation 0 0 1 1.5708
  children [
    Shape {
      geometry Box {
        size 0.3 0.3 0.3
      }
    }
  ]
  name "BOX_1"
  boundingObject Box {
    size 0.3 0.3 0.3
  }
}
DEF BOX_1 Solid {
  translation 1.10218 2.26529 0.15
  rotation 0 0 1 1.5708
  children [
    Shape {
      geometry Box {
        size 0.3 0.3 0.3
      }
    }
  ]
  name "solid(2)"
  boundingObject Box {
    size 0.3 0.3 0.3
  }
}
DEF BOX_2 Solid {
  translation 1.10719 1.83845 0.15
  rotation 0 0 -1 4.692820414042842e-06
  children [
    Shape {
      geometry Box {
        size 0.3 0.3 0.3
      }
    }
  ]
  name "solid(3)"
  boundingObject Box {
    size 0.3 0.3 0.3
  }
}
DEF CP_0 Transform {
  translation -0.72 -1.75 0.05
  children [
    DEF CP_0_Shape Shape {
      appearance DEF PBRAappearance_CP_0 PBRAppearance {
        baseColor 0 1 1
        transparency 0.5
        metalness 0
        name ""
      }
      geometry Cylinder {
        height 0.1
        radius 0.15
      }
    }
  ]
}
Robot {
  children [
    Emitter {
      type "serial"
    }
    Receiver {
      type "serial"
      channel 1
    }
  ]
  controller "Supervisor_Mundo"
  supervisor TRUE
}
