#VRML_SIM R2023a utf8

EXTERNPROTO "https://raw.githubusercontent.com/cyberbotics/webots/R2023a/projects/objects/backgrounds/protos/TexturedBackgroundLight.proto"
EXTERNPROTO "https://raw.githubusercontent.com/cyberbotics/webots/R2023a/projects/objects/floors/protos/RectangleArena.proto"
EXTERNPROTO "https://raw.githubusercontent.com/cyberbotics/webots/R2023a/projects/appearances/protos/BrushedAluminium.proto"
EXTERNPROTO "https://raw.githubusercontent.com/cyberbotics/webots/R2023a/projects/objects/apartment_structure/protos/Wall.proto"
EXTERNPROTO "https://raw.githubusercontent.com/cyberbotics/webots/R2023a/projects/appearances/protos/Parquetry.proto"

WorldInfo {
}
Viewpoint {
  orientation -0.5786351380179745 0.5723893792887661 0.5809920615019976 2.0771065147505863
  position -0.05874803553927563 -0.22038777411979282 16.41780208592415
  follow "rectangle arena"
}
TexturedBackgroundLight {
}
RectangleArena {
  floorSize 3.8 4.8
  floorAppearance Parquetry {
    type "chequered"
    colorOverride 0.392157 0.545098 0.784314
    IBLStrength 2
  }
  wallAppearance BrushedAluminium {
    IBLStrength 0
  }
}
Robot {
  translation -1.7681333519301283 -2.265069402564356 -0.0021066026450428377
  rotation 1.4849577617257276e-05 4.839582228382789e-05 -0.9999999987186673 3.1377430257752583
  children [
    DEF Body Transform {
      translation 0 0 0.0255
      children [
        Shape {
          appearance PBRAppearance {
            roughness 1
            metalness 0
          }
          geometry Cylinder {
            height 0.019
            radius 0.075
          }
        }
      ]
    }
    Transform {
      translation 0 0 0.016
      scale 0.001 0.001 0.001
      children [
        Shape {
          appearance PBRAppearance {
            roughness 1
            metalness 0
          }
          geometry Mesh {
            url [
              "../Modelos_3D/Pololu/BumperV2.stl"
            ]
          }
        }
      ]
    }
    Transform {
      translation 0 0 0.0165
      rotation 0 0 1 3.141
      scale 0.001 0.001 0.001
      children [
        Shape {
          appearance PBRAppearance {
            baseColor 0.454902 0.462745 0.419608
            roughness 1
            metalness 0
          }
          geometry Mesh {
            url [
              "../Modelos_3D/Pololu/BaseSensorDistancia.stl"
            ]
          }
        }
      ]
    }
    DEF BaseSensores Solid {
      children [
        DistanceSensor {
          translation 0 0 0.085
          rotation 0 0 -1 1.5699996938995748
          name "ds_0"
          lookupTable [
            0 0 0
            1 100 0
          ]
          type "laser"
          aperture 0.1
        }
        Compass {
          translation 0 0 0.085
          rotation 0 0 -1 1.57
        }
        DistanceSensor {
          translation 0 0 0.085
          rotation 0 0 1 -2.353185307179586
          name "ds_1"
          lookupTable [
            0 0 0
            1 100 0
          ]
        }
        DistanceSensor {
          translation 0 0 0.085
          rotation 0 0 1 3.14
          name "ds_2"
          lookupTable [
            0 0 0
            1 100 0
          ]
        }
        DistanceSensor {
          translation 0 0 0.085
          rotation 0 0 1 1.57
          name "ds_3"
          lookupTable [
            0 0 0
            1 100 0
          ]
        }
        GPS {
        }
        DistanceSensor {
          translation 0 0 0.085
          name "ds_4"
          lookupTable [
            0 0 0
            1 100 0
          ]
        }
        DistanceSensor {
          translation 0 0 0.085
          rotation 0 0 1 -0.7831853071795862
          name "ds_5"
          lookupTable [
            0 0 0
            1 100 0
          ]
        }
      ]
      name "solid(4)"
    }
    HingeJoint {
      jointParameters HingeJointParameters {
        position 129.87480345830414
        anchor 0.07 0 0.037
      }
      device [
        PositionSensor {
          name "PositionSensor_1"
        }
        RotationalMotor {
          name "motor_1"
        }
      ]
      endPoint Solid {
        translation 0.06999999999204387 -4.329353291489106e-06 0.03699548236557448
        rotation 0.6279840611656492 0.46032556131834773 0.6274841802936916 2.2781727243760175
        children [
          DEF wheel_1 Shape {
            appearance PBRAppearance {
              baseColor 0 0 0
              roughness 1
              metalness 0
            }
            geometry Cylinder {
              height 0.01
              radius 0.035
            }
          }
        ]
        contactMaterial "rubber"
        boundingObject USE wheel_1
        physics Physics {
        }
        linearVelocity -0.0005355299210611765 0.17498515711619486 -4.715015314666907e-06
        angularVelocity -5.000691874847569 -0.020610312562567096 -0.008178152612286937
      }
    }
    HingeJoint {
      jointParameters HingeJointParameters {
        position 174.1252155648255
        anchor -0.07 0 0.037
      }
      device [
        PositionSensor {
          name "PositionSensor_2"
        }
        RotationalMotor {
          name "motor_2"
        }
      ]
      endPoint Solid {
        translation -0.07000000893515845 -2.5457021279596864e-06 0.03699190839331587
        rotation -0.5525032488870706 -0.624523764979934 -0.5520056403194806 4.257475026407972
        children [
          DEF wheel_2 Shape {
            appearance PBRAppearance {
              baseColor 0 0 0
              roughness 1
              metalness 0
            }
            geometry Cylinder {
              height 0.01
              radius 0.035
            }
          }
        ]
        name "solid(1)"
        contactMaterial "rubber"
        boundingObject USE wheel_2
        physics Physics {
        }
        linearVelocity -0.0014740682482461728 0.1750234272239789 -7.79692039377219e-06
        angularVelocity -5.000654968085877 -0.030608179485680554 0.004345710941501489
      }
    }
    BallJoint {
      jointParameters BallJointParameters {
        position -8.142938976949699
        anchor 0 0.06 0.012
      }
      jointParameters2 JointParameters {
        position -11.04503186335375
        axis 1 0 0
      }
      jointParameters3 JointParameters {
        position -46.72059943281718
        axis 0 1 0
      }
      endPoint Solid {
        translation -2.317790246775253e-05 0.0600514323752086 0.01199982532237028
        rotation 0.278385288133337 -0.9114204473313267 0.3030089099965268 1.767711254242356
        children [
          DEF CasterBall_1 Shape {
            appearance PBRAppearance {
              baseColor 0.333333 0.333333 0.498039
              roughness 1
              metalness 0
            }
            geometry Sphere {
              radius 0.01
            }
          }
        ]
        name "solid(2)"
        boundingObject USE CasterBall_1
        physics Physics {
        }
        linearVelocity -0.0009817183907674751 0.175399494349983 5.236238820412649e-05
        angularVelocity -17.539949419191373 -0.09817184457988211 0.0003975125146423182
      }
    }
    BallJoint {
      jointParameters BallJointParameters {
        position 11.188247387963962
        anchor 0 -0.06 0.012
      }
      jointParameters2 JointParameters {
        position -2.0831525503979083
        axis 1 0 0
      }
      jointParameters3 JointParameters {
        position 45.59050944487511
        axis 0 1 0
      }
      endPoint Solid {
        translation 2.306034731103246e-05 -0.0600518344247174 0.01199978469415002
        rotation 0.7266442753117314 0.5554692845964299 0.404279570379977 2.5122886702366185
        children [
          DEF CasterBall_2 Shape {
            appearance PBRAppearance {
              baseColor 0.333333 0.333333 0.498039
              roughness 1
              metalness 0
            }
            geometry Sphere {
              radius 0.01
            }
          }
        ]
        name "solid(3)"
        boundingObject USE CasterBall_2
        physics Physics {
        }
        linearVelocity -0.001031996922461202 0.17459600894634456 -3.786160062512748e-05
        angularVelocity -17.45960085927478 -0.10319971406139247 -0.0011060663997441988
      }
    }
  ]
  contactMaterial "plastic"
  boundingObject USE Body
  physics Physics {
  }
  controller "my_controller_Pololu3pi"
  selfCollision TRUE
  linearVelocity -0.0010059438144231407 0.17502661956840146 1.45875431021609e-05
  angularVelocity -0.0007346724295140506 7.47179935771304e-05 0.0034710764946145876
}
Wall {
  translation -1.1 -0.44 0
  size 1 0.08 0.1
}
Wall {
  translation -0.9 1.06 0
  name "wall(8)"
  size 2 0.08 0.1
}
Wall {
  translation -0.59 0.67 0
  name "wall(2)"
  size 2 0.08 0.1
}
Wall {
  translation -1.03 -2.35 0
  name "wall(7)"
  size 1 0.08 0.1
}
Wall {
  translation 0.0699933 2.03001 0
  rotation 0 0 1 1.5708
  name "wall(9)"
  size 2 0.08 0.1
}
Wall {
  translation 0.45 1.42001 0
  rotation 0 0 1 1.5708
  name "wall(10)"
  size 2 0.08 0.1
}
Wall {
  translation -1.56 -0.28999 0
  rotation 0 0 1 1.5708
  name "wall(1)"
  size 2 0.08 0.1
}
Wall {
  translation -1.57 -1.39999 0
  rotation 0 0 1 1.5708
  name "wall(4)"
  size 2 0.08 0.1
}
Solid {
  translation 1.69 2.03 0.001
  children [
    Shape {
      geometry Plane {
        size 0.4 0.4
      }
    }
  ]
}
