#VRML_SIM R2023a utf8

EXTERNPROTO "https://raw.githubusercontent.com/cyberbotics/webots/R2023a/projects/objects/backgrounds/protos/TexturedBackgroundLight.proto"
EXTERNPROTO "https://raw.githubusercontent.com/cyberbotics/webots/R2023a/projects/objects/floors/protos/RectangleArena.proto"
EXTERNPROTO "https://raw.githubusercontent.com/cyberbotics/webots/R2023a/projects/objects/apartment_structure/protos/Wall.proto"
EXTERNPROTO "https://raw.githubusercontent.com/cyberbotics/webots/R2023a/projects/appearances/protos/Parquetry.proto"

WorldInfo {
}
Viewpoint {
  orientation -0.5812779773465931 0.5748690569428858 0.5758832176938744 2.0843378416970944
  position -0.5270714616904792 -0.04240623159974111 7.884986323663809
  follow "rectangle arena"
}
TexturedBackgroundLight {
}
RectangleArena {
  floorSize 5 5
  floorAppearance Parquetry {
    type "chequered"
    colorOverride 0.392157 0.545098 0.784314
    IBLStrength 6
  }
}
Robot {
  translation -2.34874 -2.10735 -0.00210856
  rotation 1.4849577617257276e-05 4.839582228382789e-05 -0.9999999987186673 3.1377430257752583
  children [
    DEF Body Transform {
      translation 0 0 0.0255
      children [
        Shape {
          appearance PBRAppearance {
            roughness 1
            metalness 0
          }
          geometry Cylinder {
            height 0.019
            radius 0.075
          }
        }
      ]
    }
    Transform {
      translation 0 0 0.016
      scale 0.001 0.001 0.001
      children [
        Shape {
          appearance PBRAppearance {
            roughness 1
            metalness 0
          }
          geometry Mesh {
            url [
              "../Modelos_3D/Pololu/BumperV2.stl"
            ]
          }
        }
      ]
    }
    Transform {
      translation 0 0 0.0165
      rotation 0 0 1 3.141
      scale 0.001 0.001 0.001
      children [
        Shape {
          appearance PBRAppearance {
            baseColor 0.454902 0.462745 0.419608
            roughness 1
            metalness 0
          }
          geometry Mesh {
            url [
              "../Modelos_3D/Pololu/BaseSensorDistancia.stl"
            ]
          }
        }
      ]
    }
    DEF BaseSensores Solid {
      children [
        DistanceSensor {
          translation 0 0 0.085
          rotation 0 0 -1 1.5699996938995748
          name "ds_0"
          lookupTable [
            0 0 0
            2 200 0
          ]
          type "laser"
          aperture 0.1
        }
        Compass {
          translation 0 0 0.085
          rotation 0 0 -1 1.57
        }
        DistanceSensor {
          translation 0 0 0.085
          rotation 0 0 1 -2.353185307179586
          name "ds_1"
          lookupTable [
            0 0 0
            2 200 0
          ]
        }
        DistanceSensor {
          translation 0 0 0.085
          rotation 0 0 1 3.14
          name "ds_2"
          lookupTable [
            0 0 0
            2 200 0
          ]
        }
        DistanceSensor {
          translation 0 0 0.085
          rotation 0 0 1 1.57
          name "ds_3"
          lookupTable [
            0 0 0
            2 200 0
          ]
        }
        GPS {
        }
        DistanceSensor {
          translation 0 0 0.085
          name "ds_4"
          lookupTable [
            0 0 0
            2 200 0
          ]
          resolution 2
        }
        DistanceSensor {
          translation 0 0 0.085
          rotation 0 0 1 -0.7831853071795862
          name "ds_5"
          lookupTable [
            0 0 0
            2 200 0
          ]
        }
      ]
      name "solid(4)"
    }
    HingeJoint {
      jointParameters HingeJointParameters {
        position 129.87480345830414
        anchor 0.07 0 0.037
      }
      device [
        PositionSensor {
          name "PositionSensor_1"
        }
        RotationalMotor {
          name "motor_1"
        }
      ]
      endPoint Solid {
        translation 0.06999999999204387 -4.329353291487266e-06 0.03699548236557448
        rotation 0.6279840611656493 0.4603255613183475 0.6274841802936919 2.278172724376016
        children [
          DEF wheel_1 Shape {
            appearance PBRAppearance {
              baseColor 0 0 0
              roughness 1
              metalness 0
            }
            geometry Cylinder {
              height 0.01
              radius 0.035
            }
          }
        ]
        contactMaterial "rubber"
        boundingObject USE wheel_1
        physics Physics {
        }
      }
    }
    HingeJoint {
      jointParameters HingeJointParameters {
        position 174.1252155648255
        anchor -0.07 0 0.037
      }
      device [
        PositionSensor {
          name "PositionSensor_2"
        }
        RotationalMotor {
          name "motor_2"
        }
      ]
      endPoint Solid {
        translation -0.07000000893515845 -2.545702127960275e-06 0.03699190839331587
        rotation -0.5525032488870706 -0.6245237649799341 -0.5520056403194807 4.257475026407972
        children [
          DEF wheel_2 Shape {
            appearance PBRAppearance {
              baseColor 0 0 0
              roughness 1
              metalness 0
            }
            geometry Cylinder {
              height 0.01
              radius 0.035
            }
          }
        ]
        name "solid(1)"
        contactMaterial "rubber"
        boundingObject USE wheel_2
        physics Physics {
        }
      }
    }
    BallJoint {
      jointParameters BallJointParameters {
        position -8.142938976949699
        anchor 0 0.06 0.012
      }
      jointParameters2 JointParameters {
        position -11.04503186335375
        axis 1 0 0
      }
      jointParameters3 JointParameters {
        position -46.72059943281718
        axis 0 1 0
      }
      endPoint Solid {
        translation -2.3177902467753968e-05 0.0600514323752086 0.011999825322370278
        rotation 0.27838528813333974 -0.9114204473313264 0.3030089099965249 1.7677112542423583
        children [
          DEF CasterBall_1 Shape {
            appearance PBRAppearance {
              baseColor 0.333333 0.333333 0.498039
              roughness 1
              metalness 0
            }
            geometry Sphere {
              radius 0.01
            }
          }
        ]
        name "solid(2)"
        boundingObject USE CasterBall_1
        physics Physics {
        }
      }
    }
    BallJoint {
      jointParameters BallJointParameters {
        position 11.188247387963962
        anchor 0 -0.06 0.012
      }
      jointParameters2 JointParameters {
        position -2.0831525503979083
        axis 1 0 0
      }
      jointParameters3 JointParameters {
        position 45.59050944487511
        axis 0 1 0
      }
      endPoint Solid {
        translation 2.3060347311030727e-05 -0.0600518344247174 0.011999784694150018
        rotation 0.7266442753117307 0.5554692845964304 0.4042795703799779 2.512288670236619
        children [
          DEF CasterBall_2 Shape {
            appearance PBRAppearance {
              baseColor 0.333333 0.333333 0.498039
              roughness 1
              metalness 0
            }
            geometry Sphere {
              radius 0.01
            }
          }
        ]
        name "solid(3)"
        boundingObject USE CasterBall_2
        physics Physics {
        }
      }
    }
  ]
  contactMaterial "plastic"
  boundingObject USE Body
  physics Physics {
  }
  controller "my_controller_Pololu3pi"
  selfCollision TRUE
}
Wall {
  translation 0.33 -0.55 0
  size 1 0.08 0.1
}
Wall {
  translation -0.03 -2.32 0
  name "wall(3)"
  size 1 0.08 0.1
}
Wall {
  translation -0.91 2.43 0
  name "wall(8)"
  size 3.2 0.08 0.1
}
Wall {
  translation -1.09 1.46 0
  name "wall(2)"
  size 2 0.08 0.1
}
Wall {
  translation 0.76 0.43 0
  name "wall(7)"
  size 1 0.08 0.1
}
Wall {
  translation 0.65999 1.46 0
  rotation 0 0 1 1.5708
  name "wall(9)"
  size 2 0.08 0.1
}
Wall {
  translation 0.300002 1.45001 0
  rotation 0 0 1 1.5708
  name "wall(10)"
  size 2 0.08 0.1
}
Wall {
  translation -2.13 -0.49999 0
  rotation 0 0 1 1.5708
  name "wall(1)"
  size 4 0.08 0.1
}
Wall {
  translation -0.130006 0.49001 0
  rotation 0 0 1 1.5708
  name "wall(4)"
  size 2 0.08 0.1
}
Solid {
  translation -2.32 -2.11 0.001
  children [
    Shape {
      appearance PBRAppearance {
        baseColor 0 1 0
        roughness 1
        metalness 0
      }
      geometry Plane {
        size 0.25 0.25
      }
    }
  ]
}
Solid {
  translation -1.21282 -1.66 0.15
  rotation 0 0 1 0.523599
  children [
    Shape {
      geometry Box {
        size 0.3 0.3 0.3
      }
    }
  ]
  name "solid(1)"
  boundingObject Box {
    size 0.3 0.3 0.3
  }
}
