#VRML_SIM R2023a utf8

EXTERNPROTO "https://raw.githubusercontent.com/cyberbotics/webots/R2023a/projects/objects/backgrounds/protos/TexturedBackground.proto"
EXTERNPROTO "https://raw.githubusercontent.com/cyberbotics/webots/R2023a/projects/objects/backgrounds/protos/TexturedBackgroundLight.proto"
EXTERNPROTO "https://raw.githubusercontent.com/cyberbotics/webots/R2023a/projects/objects/floors/protos/RectangleArena.proto"
EXTERNPROTO "https://raw.githubusercontent.com/cyberbotics/webots/R2023a/projects/appearances/protos/Parquetry.proto"
EXTERNPROTO "https://raw.githubusercontent.com/cyberbotics/webots/R2023a/projects/appearances/protos/BrushedAluminium.proto"
EXTERNPROTO "https://raw.githubusercontent.com/cyberbotics/webots/R2023a/projects/objects/apartment_structure/protos/Wall.proto"

WorldInfo {
}
Viewpoint {
  orientation 0.5844377729286134 -0.5787467463970196 -0.5687571477433108 4.188485761701635
  position -0.34262039674395056 0.12388728817052409 7.735983217391954
  follow "rectangle arena"
}
TexturedBackground {
  texture "dawn_cloudy_empty"
}
TexturedBackgroundLight {
}
RectangleArena {
  floorSize 3.8 4.8
  floorAppearance Parquetry {
  }
  wallAppearance BrushedAluminium {
    colorOverride 0.419608 0.941176 1
    IBLStrength 100
  }
}
Robot {
  translation -1.2849 -1.87295 -0.00211685
  rotation -0.00015240974432383504 -0.0010489664955574084 -0.9999994382201226 0.008909482615185822
  children [
    DEF Body Transform {
      translation 0 0 0.0255
      children [
        Shape {
          appearance PBRAppearance {
            roughness 1
            metalness 0
          }
          geometry Cylinder {
            height 0.019
            radius 0.075
          }
        }
      ]
    }
    Transform {
      translation 0 0 0.016
      scale 0.001 0.001 0.001
      children [
        Shape {
          appearance PBRAppearance {
            roughness 1
            metalness 0
          }
          geometry Mesh {
            url [
              "../Modelos_3D/Pololu/BumperV2.stl"
            ]
          }
        }
      ]
    }
    Transform {
      translation 0 0 0.0165
      rotation 0 0 1 3.141
      scale 0.001 0.001 0.001
      children [
        Shape {
          appearance PBRAppearance {
            baseColor 0.454902 0.462745 0.419608
            roughness 1
            metalness 0
          }
          geometry Mesh {
            url [
              "../Modelos_3D/Pololu/BaseSensorDistancia.stl"
            ]
          }
        }
      ]
    }
    DEF BaseSensores Solid {
      children [
        DistanceSensor {
          translation 0 0 0.085
          rotation 0 0 -1 1.5699996938995748
          name "ds_0"
          lookupTable [
            0 0 0
            1 100 0
          ]
          type "laser"
          aperture 0.1
        }
        Compass {
          translation 0 0 0.085
          rotation 0 0 -1 1.57
        }
        DistanceSensor {
          translation 0 0 0.085
          rotation 0 0 1 -2.353185307179586
          name "ds_1"
          lookupTable [
            0 0 0
            1 100 0
          ]
        }
        DistanceSensor {
          translation 0 0 0.085
          rotation 0 0 1 3.14
          name "ds_2"
          lookupTable [
            0 0 0
            1 100 0
          ]
        }
        DistanceSensor {
          translation 0 0 0.085
          rotation 0 0 1 1.57
          name "ds_3"
          lookupTable [
            0 0 0
            1 100 0
          ]
        }
        DistanceSensor {
          translation 0 0 0.085
          name "ds_4"
          lookupTable [
            0 0 0
            1 100 0
          ]
        }
        DistanceSensor {
          translation 0 0 0.085
          rotation 0 0 1 -0.7831853071795862
          name "ds_5"
          lookupTable [
            0 0 0
            1 100 0
          ]
        }
      ]
      name "solid(4)"
    }
    HingeJoint {
      jointParameters HingeJointParameters {
        position 122.84124873320663
        anchor 0.07 0 0.037
      }
      device [
        PositionSensor {
          name "PositionSensor_1"
        }
        RotationalMotor {
          name "motor_1"
        }
      ]
      endPoint Solid {
        translation 0.06999999999204387 -6.247264853957855e-06 0.03699964786001401
        rotation -0.4709671286544881 -0.7461453693881194 -0.4705922348144023 4.424415256590024
        children [
          DEF wheel_1 Shape {
            appearance PBRAppearance {
              baseColor 0 0 0
              roughness 1
              metalness 0
            }
            geometry Cylinder {
              height 0.01
              radius 0.035
            }
          }
        ]
        contactMaterial "rubber"
        boundingObject USE wheel_1
        physics Physics {
        }
      }
    }
    HingeJoint {
      jointParameters HingeJointParameters {
        position 179.23876991820774
        anchor -0.07 0 0.037
      }
      device [
        PositionSensor {
          name "PositionSensor_2"
        }
        RotationalMotor {
          name "motor_2"
        }
      ]
      endPoint Solid {
        translation -0.07000000000794648 -6.218934986892658e-06 0.03700059157295426
        rotation 0.7073014811780948 -0.015663995474606 0.7067384622114781 3.1729430336351316
        children [
          DEF wheel_2 Shape {
            appearance PBRAppearance {
              baseColor 0 0 0
              roughness 1
              metalness 0
            }
            geometry Cylinder {
              height 0.01
              radius 0.035
            }
          }
        ]
        name "solid(1)"
        contactMaterial "rubber"
        boundingObject USE wheel_2
        physics Physics {
        }
      }
    }
    BallJoint {
      jointParameters BallJointParameters {
        position -8.63021309416183
        anchor 0 0.06 0.012
      }
      jointParameters2 JointParameters {
        position -11.08250831864482
        axis 1 0 0
      }
      jointParameters3 JointParameters {
        position -46.564548563530316
        axis 0 1 0
      }
      endPoint Solid {
        translation 1.1334910868795399e-07 0.05999999821282377 0.01200001606898769
        rotation -0.6557636606892912 0.27297485221838297 0.7038883088784273 2.9251196457371815
        children [
          DEF CasterBall_1 Shape {
            appearance PBRAppearance {
              baseColor 0.333333 0.333333 0.498039
              roughness 1
              metalness 0
            }
            geometry Sphere {
              radius 0.01
            }
          }
        ]
        name "solid(2)"
        boundingObject USE CasterBall_1
        physics Physics {
        }
      }
    }
    BallJoint {
      jointParameters BallJointParameters {
        position 11.137499168263107
        anchor 0 -0.06 0.012
      }
      jointParameters2 JointParameters {
        position -2.085711927665663
        axis 1 0 0
      }
      jointParameters3 JointParameters {
        position 45.59233521307966
        axis 0 1 0
      }
      endPoint Solid {
        translation -6.531905823452563e-10 -0.059999966416294605 0.01200000363250776
        rotation -0.4969062806228106 0.5534646613066342 -0.6684018379405741 1.7410826508297927
        children [
          DEF CasterBall_2 Shape {
            appearance PBRAppearance {
              baseColor 0.333333 0.333333 0.498039
              roughness 1
              metalness 0
            }
            geometry Sphere {
              radius 0.01
            }
          }
        ]
        name "solid(3)"
        boundingObject USE CasterBall_2
        physics Physics {
        }
      }
    }
  ]
  contactMaterial "plastic"
  boundingObject USE Body
  physics Physics {
  }
  controller "my_controller_Pololu3pi"
  selfCollision TRUE
}
Wall {
  translation -0.81 1.53 0
  size 1.5 0.08 0.1
}
Wall {
  translation 0.83 0.52 0
  name "wall(1)"
  size 1.5 0.08 0.1
}
Wall {
  translation 0.62 -1.56 0
  name "wall(5)"
  size 1.5 0.08 0.1
}
Wall {
  translation -0.61 -0.59 0
  name "wall(3)"
  size 1.5 0.08 0.1
}
Wall {
  translation -0.810002 -0.42 0
  rotation 0 0 1 1.5708
  name "wall(2)"
  size 4 0.05 0.1
}
Wall {
  translation 0.719998 0.4 0
  rotation 0 0 1 1.5708
  name "wall(4)"
  size 4 0.05 0.1
}
