#VRML_SIM R2023a utf8

EXTERNPROTO "https://raw.githubusercontent.com/cyberbotics/webots/R2023a/projects/objects/backgrounds/protos/TexturedBackground.proto"
EXTERNPROTO "https://raw.githubusercontent.com/cyberbotics/webots/R2023a/projects/objects/backgrounds/protos/TexturedBackgroundLight.proto"
EXTERNPROTO "https://raw.githubusercontent.com/cyberbotics/webots/R2023a/projects/objects/floors/protos/RectangleArena.proto"
EXTERNPROTO "https://raw.githubusercontent.com/cyberbotics/webots/R2023a/projects/appearances/protos/Parquetry.proto"
EXTERNPROTO "https://raw.githubusercontent.com/cyberbotics/webots/R2023a/projects/appearances/protos/BrushedAluminium.proto"
EXTERNPROTO "https://raw.githubusercontent.com/cyberbotics/webots/R2023a/projects/objects/apartment_structure/protos/Wall.proto"

WorldInfo {
}
Viewpoint {
  orientation 0.5770314596122846 -0.5696969466674561 -0.5852179795388162 4.2107310837319645
  position 0.07765066406971638 -0.20882281249258935 6.660180501602723
  follow "rectangle arena"
}
TexturedBackground {
  texture "dawn_cloudy_empty"
}
TexturedBackgroundLight {
}
RectangleArena {
  floorSize 2 2
  floorAppearance Parquetry {
  }
  wallAppearance BrushedAluminium {
    colorOverride 0.419608 0.941176 1
    IBLStrength 100
  }
}
Robot {
  translation -0.5100127375473883 -0.15225603507848737 -0.0021118634411798586
  rotation -0.45008252048604885 0.8111264174548725 0.37349653232627145 7.902372070876123e-05
  children [
    DEF Body Transform {
      translation 0 0 0.0255
      children [
        Shape {
          appearance PBRAppearance {
            roughness 1
            metalness 0
          }
          geometry Cylinder {
            height 0.019
            radius 0.075
          }
        }
      ]
    }
    Transform {
      translation 0 0 0.016
      scale 0.001 0.001 0.001
      children [
        Shape {
          appearance PBRAppearance {
            roughness 1
            metalness 0
          }
          geometry Mesh {
            url [
              "../Modelos_3D/Pololu/BumperV2.stl"
            ]
          }
        }
      ]
    }
    Transform {
      translation 0 0 0.0165
      rotation 0 0 1 3.141
      scale 0.001 0.001 0.001
      children [
        Shape {
          appearance PBRAppearance {
            baseColor 0.454902 0.462745 0.419608
            roughness 1
            metalness 0
          }
          geometry Mesh {
            url [
              "../Modelos_3D/Pololu/BaseSensorDistancia.stl"
            ]
          }
        }
      ]
    }
    DEF BaseSensores Solid {
      children [
        DistanceSensor {
          translation 0 0 0.085
          rotation 0 0 -1 1.5699996938995748
          name "ds_0"
          lookupTable [
            0 0 0
            1 100 0
          ]
          type "laser"
          aperture 0.05
        }
        Compass {
          translation 0 0 0.085
          rotation 0 0 -1 1.57
        }
        DistanceSensor {
          translation 0 0 0.085
          rotation 0 0 1 -2.618185307179586
          name "ds_1"
          lookupTable [
            0 0 0
            1 100 0
          ]
        }
        DistanceSensor {
          translation 0 0 0.085
          rotation 0 0 1 2.61
          name "ds_2"
          lookupTable [
            0 0 0
            1 100 0
          ]
        }
        DistanceSensor {
          translation 0 0 0.085
          rotation 0 0 1 1.57
          name "ds_3"
          lookupTable [
            0 0 0
            1 100 0
          ]
        }
        DistanceSensor {
          translation 0 0 0.085
          rotation 0 0 1 0.52
          name "ds_4"
          lookupTable [
            0 0 0
            1 100 0
          ]
        }
        DistanceSensor {
          translation 0 0 0.085
          rotation 0 0 -1 0.523
          name "ds_5"
          lookupTable [
            0 0 0
            1 100 0
          ]
        }
      ]
      name "solid(4)"
    }
    HingeJoint {
      jointParameters HingeJointParameters {
        position 2.821771768394136
        anchor 0.07 0 0.037
      }
      device [
        PositionSensor {
          name "PositionSensor_1"
        }
        RotationalMotor {
          name "motor_1"
        }
      ]
      endPoint Solid {
        translation 0.06999999999204387 -5.224797861166778e-06 0.03700344293596154
        rotation 0.23430065208408293 0.9435537984687065 0.23411414700579125 1.6280705574147172
        children [
          DEF wheel_1 Shape {
            appearance PBRAppearance {
              baseColor 0 0 0
              roughness 1
              metalness 0
            }
            geometry Cylinder {
              height 0.01
              radius 0.035
            }
          }
        ]
        contactMaterial "rubber"
        boundingObject USE wheel_1
        physics Physics {
        }
      }
    }
    HingeJoint {
      jointParameters HingeJointParameters {
        position 6.138227681106741
        anchor -0.07 0 0.037
      }
      device [
        PositionSensor {
          name "PositionSensor_2"
        }
        RotationalMotor {
          name "motor_2"
        }
      ]
      endPoint Solid {
        translation -0.07000000000794648 5.734761817725246e-06 0.036997522578391596
        rotation 0.13282868588848953 -0.9822123792757191 0.13272295281023438 4.695238426234023
        children [
          DEF wheel_2 Shape {
            appearance PBRAppearance {
              baseColor 0 0 0
              roughness 1
              metalness 0
            }
            geometry Cylinder {
              height 0.01
              radius 0.035
            }
          }
        ]
        name "solid(1)"
        contactMaterial "rubber"
        boundingObject USE wheel_2
        physics Physics {
        }
      }
    }
    BallJoint {
      jointParameters BallJointParameters {
        position -9.663640267290317
        anchor 0 0.06 0.012
      }
      jointParameters2 JointParameters {
        position -5.814155942384379
        axis 1 0 0
      }
      jointParameters3 JointParameters {
        position -37.658863612858696
        axis 0 1 0
      }
      endPoint Solid {
        translation 2.9592432381178696e-08 0.05999989231300767 0.01200002524334433
        rotation -0.9152605900277662 -0.19717123377467297 0.35131404314914383 1.398879427193493
        children [
          DEF CasterBall_1 Shape {
            appearance PBRAppearance {
              baseColor 0.333333 0.333333 0.498039
              roughness 1
              metalness 0
            }
            geometry Sphere {
              radius 0.01
            }
          }
        ]
        name "solid(2)"
        boundingObject USE CasterBall_1
        physics Physics {
        }
      }
    }
    BallJoint {
      jointParameters BallJointParameters {
        position 9.4756659028517
        anchor 0 -0.06 0.012
      }
      jointParameters2 JointParameters {
        position -5.560557180007866
        axis 1 0 0
      }
      jointParameters3 JointParameters {
        position 38.09758909493188
        axis 0 1 0
      }
      endPoint Solid {
        translation -2.335607763948316e-08 -0.06000001990019235 0.011999985859171884
        rotation -0.46425999985613053 -0.6518074742444282 0.5996746359924563 1.0419875530556353
        children [
          DEF CasterBall_2 Shape {
            appearance PBRAppearance {
              baseColor 0.333333 0.333333 0.498039
              roughness 1
              metalness 0
            }
            geometry Sphere {
              radius 0.01
            }
          }
        ]
        name "solid(3)"
        boundingObject USE CasterBall_2
        physics Physics {
        }
      }
    }
  ]
  contactMaterial "plastic"
  boundingObject USE Body
  physics Physics {
  }
  controller "my_controller_Pololu3pi"
  selfCollision TRUE
}
Wall {
  translation -0.5 0.45 0
  size 1 0.01 0.1
}
Wall {
  translation 0.12 0.22 0
  name "wall(4)"
  size 1 0.01 0.1
}
Wall {
  translation 0.15 0.73 0
  name "wall(5)"
  size 1 0.01 0.1
}
Wall {
  translation -0.66 -0.060001 0
  rotation 0 0 1 1.5708
  name "wall(1)"
  size 1 0.01 0.1
}
Wall {
  translation -0.39 -0.280001 0
  rotation 0 0 1 1.5708
  name "wall(2)"
  size 1 0.01 0.1
}
Wall {
  translation 0.65 0.239999 0
  rotation 0 0 1 1.5708
  name "wall(3)"
  size 1 0.01 0.1
}
