#VRML_SIM R2023a utf8

EXTERNPROTO "https://raw.githubusercontent.com/cyberbotics/webots/R2023a/projects/objects/backgrounds/protos/TexturedBackgroundLight.proto"
EXTERNPROTO "https://raw.githubusercontent.com/cyberbotics/webots/R2023a/projects/objects/floors/protos/RectangleArena.proto"
EXTERNPROTO "https://raw.githubusercontent.com/cyberbotics/webots/R2023a/projects/appearances/protos/BrushedAluminium.proto"
EXTERNPROTO "https://raw.githubusercontent.com/cyberbotics/webots/R2023a/projects/objects/apartment_structure/protos/Wall.proto"
EXTERNPROTO "https://raw.githubusercontent.com/cyberbotics/webots/R2023a/projects/appearances/protos/Parquetry.proto"

WorldInfo {
}
Viewpoint {
  orientation -0.574718718552856 0.5676535571411562 0.5894640223202392 2.065724936049814
  position -0.3476389986027889 -1.225859239259474 13.848362156934325
  follow "rectangle arena"
}
TexturedBackgroundLight {
}
RectangleArena {
  floorSize 3.8 4.8
  floorAppearance Parquetry {
    type "chequered"
    colorOverride 0.392157 0.545098 0.784314
    IBLStrength 2
  }
  wallAppearance BrushedAluminium {
    IBLStrength 0
  }
}
Robot {
  translation -1.76886 -2.29885 -0.00212062
  rotation -0.00015240974432383504 -0.0010489664955574084 -0.9999994382201226 0.008909482615185822
  children [
    DEF Body Transform {
      translation 0 0 0.0255
      children [
        Shape {
          appearance PBRAppearance {
            roughness 1
            metalness 0
          }
          geometry Cylinder {
            height 0.019
            radius 0.075
          }
        }
      ]
    }
    Transform {
      translation 0 0 0.016
      scale 0.001 0.001 0.001
      children [
        Shape {
          appearance PBRAppearance {
            roughness 1
            metalness 0
          }
          geometry Mesh {
            url [
              "../Modelos_3D/Pololu/BumperV2.stl"
            ]
          }
        }
      ]
    }
    Transform {
      translation 0 0 0.0165
      rotation 0 0 1 3.141
      scale 0.001 0.001 0.001
      children [
        Shape {
          appearance PBRAppearance {
            baseColor 0.454902 0.462745 0.419608
            roughness 1
            metalness 0
          }
          geometry Mesh {
            url [
              "../Modelos_3D/Pololu/BaseSensorDistancia.stl"
            ]
          }
        }
      ]
    }
    DEF BaseSensores Solid {
      children [
        DistanceSensor {
          translation 0 0 0.085
          rotation 0 0 -1 1.5699996938995748
          name "ds_0"
          lookupTable [
            0 0 0
            1 100 0
          ]
          type "laser"
          aperture 0.1
        }
        Compass {
          translation 0 0 0.085
          rotation 0 0 -1 1.57
        }
        DistanceSensor {
          translation 0 0 0.085
          rotation 0 0 1 -2.353185307179586
          name "ds_1"
          lookupTable [
            0 0 0
            1 100 0
          ]
        }
        DistanceSensor {
          translation 0 0 0.085
          rotation 0 0 1 3.14
          name "ds_2"
          lookupTable [
            0 0 0
            1 100 0
          ]
        }
        DistanceSensor {
          translation 0 0 0.085
          rotation 0 0 1 1.57
          name "ds_3"
          lookupTable [
            0 0 0
            1 100 0
          ]
        }
        DistanceSensor {
          translation 0 0 0.085
          name "ds_4"
          lookupTable [
            0 0 0
            1 100 0
          ]
        }
        DistanceSensor {
          translation 0 0 0.085
          rotation 0 0 1 -0.7831853071795862
          name "ds_5"
          lookupTable [
            0 0 0
            1 100 0
          ]
        }
      ]
      name "solid(4)"
    }
    HingeJoint {
      jointParameters HingeJointParameters {
        position 122.84124873320663
        anchor 0.07 0 0.037
      }
      device [
        PositionSensor {
          name "PositionSensor_1"
        }
        RotationalMotor {
          name "motor_1"
        }
      ]
      endPoint Solid {
        translation 0.06999999999204387 -6.247264853957978e-06 0.03699964786001401
        rotation -0.4709671286544881 -0.7461453693881194 -0.4705922348144023 4.424415256590024
        children [
          DEF wheel_1 Shape {
            appearance PBRAppearance {
              baseColor 0 0 0
              roughness 1
              metalness 0
            }
            geometry Cylinder {
              height 0.01
              radius 0.035
            }
          }
        ]
        contactMaterial "rubber"
        boundingObject USE wheel_1
        physics Physics {
        }
      }
    }
    HingeJoint {
      jointParameters HingeJointParameters {
        position 179.23876991820774
        anchor -0.07 0 0.037
      }
      device [
        PositionSensor {
          name "PositionSensor_2"
        }
        RotationalMotor {
          name "motor_2"
        }
      ]
      endPoint Solid {
        translation -0.07000000000794648 -6.218934986890633e-06 0.03700059157295426
        rotation 0.7073014811780947 -0.015663995474605823 0.706738462211478 3.1729430336351316
        children [
          DEF wheel_2 Shape {
            appearance PBRAppearance {
              baseColor 0 0 0
              roughness 1
              metalness 0
            }
            geometry Cylinder {
              height 0.01
              radius 0.035
            }
          }
        ]
        name "solid(1)"
        contactMaterial "rubber"
        boundingObject USE wheel_2
        physics Physics {
        }
      }
    }
    BallJoint {
      jointParameters BallJointParameters {
        position -8.63021309416183
        anchor 0 0.06 0.012
      }
      jointParameters2 JointParameters {
        position -11.08250831864482
        axis 1 0 0
      }
      jointParameters3 JointParameters {
        position -46.564548563530316
        axis 0 1 0
      }
      endPoint Solid {
        translation 1.1334910868795399e-07 0.05999999821282377 0.01200001606898769
        rotation -0.6557636606892912 0.2729748522183828 0.7038883088784275 2.925119645737182
        children [
          DEF CasterBall_1 Shape {
            appearance PBRAppearance {
              baseColor 0.333333 0.333333 0.498039
              roughness 1
              metalness 0
            }
            geometry Sphere {
              radius 0.01
            }
          }
        ]
        name "solid(2)"
        boundingObject USE CasterBall_1
        physics Physics {
        }
      }
    }
    BallJoint {
      jointParameters BallJointParameters {
        position 11.137499168263107
        anchor 0 -0.06 0.012
      }
      jointParameters2 JointParameters {
        position -2.085711927665663
        axis 1 0 0
      }
      jointParameters3 JointParameters {
        position 45.59233521307966
        axis 0 1 0
      }
      endPoint Solid {
        translation -6.531905823452563e-10 -0.059999966416294605 0.01200000363250776
        rotation -0.4969062806228106 0.5534646613066342 -0.6684018379405741 1.7410826508297927
        children [
          DEF CasterBall_2 Shape {
            appearance PBRAppearance {
              baseColor 0.333333 0.333333 0.498039
              roughness 1
              metalness 0
            }
            geometry Sphere {
              radius 0.01
            }
          }
        ]
        name "solid(3)"
        boundingObject USE CasterBall_2
        physics Physics {
        }
      }
    }
  ]
  contactMaterial "plastic"
  boundingObject USE Body
  physics Physics {
  }
  controller "my_controller_Pololu3pi"
  selfCollision TRUE
}
Wall {
  translation -1.15 -0.44 0
  size 1 0.08 0.1
}
Wall {
  translation -0.9 -0.07 0
  name "wall(8)"
  size 2 0.08 0.1
}
Wall {
  translation 1.86 -0.37 0
  name "wall(2)"
  size 2 0.08 0.1
}
Wall {
  translation -0.64 1.04 0
  name "wall(7)"
  size 1 0.08 0.1
}
Wall {
  translation -0.69 -1.39999 0
  rotation 0 0 1 1.5708
  name "wall(9)"
  size 2 0.08 0.1
}
Wall {
  translation 0.9 -1.39999 0
  rotation 0 0 1 1.5708
  name "wall(10)"
  size 2 0.08 0.1
}
Wall {
  translation -0.0999969 -0.51999 0
  rotation 0 0 1 1.5708
  name "wall(1)"
  size 2 0.08 0.1
}
Wall {
  translation -1.61 -1.39999 0
  rotation 0 0 1 1.5708
  name "wall(4)"
  size 2 0.08 0.1
}
Solid {
  translation 1.69 2.03 0.001
  children [
    Shape {
      geometry Plane {
        size 0.4 0.4
      }
    }
  ]
}
